Workbook

Sheet ROSTER
A2: AGENT ROSTER — EAST HAMPTON FLAGSHIP (BASE CASE)
A3: AGENT | B3: OFFICE | C3: ROLE | D3: STATUS | E3: START | F3: YEAR 1 GCI | G3: GROWTH | H3: CAP | I3: 2026 GCI | J3: 2027 GCI | K3: 2028 GCI | L3: 2029 GCI | M3: 2030 GCI | N3: 2031 GCI | O3: SPLIT | P3: ATT | Q3: NOTES
A4: EXISTING AGENTS (8)
A5: Ed Bruehl | B5: EH | C5: Managing Director | D5: Active (At Cap) | E5: 2025 | F5: 750000 | G5: 0.2 | H5: 1000000 | I5: =F5 -> 750000 | J5: =MIN(I5*(1+G5),H5) -> 900000 | K5: =MIN(J5*(1+G5),H5) -> 1000000 | L5: =MIN(K5*(1+G5),H5) -> 1000000 | M5: =MIN(L5*(1+G5),H5) -> 1000000 | N5: =MIN(M5*(1+G5),H5) -> 1000000 | O5: 50/50 | P5: N | Q5: Team lead. At cap.
A6: Angel Theodore | B6: EH | C6: Mktg Coord + Sales | D6: Active | E6: 2025 | F6: 60000 | G6: 0.2 | H6: 1000000 | I6: =F6 -> 60000 | J6: =MIN(I6*(1+G6),H6) -> 72000 | K6: =MIN(J6*(1+G6),H6) -> 86400 | L6: =MIN(K6*(1+G6),H6) -> 103680 | M6: =MIN(L6*(1+G6),H6) -> 124416 | N6: =MIN(M6*(1+G6),H6) -> 149299.2 | O6: 70/30 | P6: N | Q6: Marketing coordinator
A7: Jarvis Slade | B7: EH | C7: Agent | D7: Active | E7: 2026 | F7: 330000 | G7: 0.2 | H7: 1000000 | I7: =F7 -> 330000 | J7: =MIN(I7*(1+G7),H7) -> 396000 | K7: =MIN(J7*(1+G7),H7) -> 475200 | L7: =MIN(K7*(1+G7),H7) -> 570240 | M7: =MIN(L7*(1+G7),H7) -> 684288 | N7: =MIN(M7*(1+G7),H7) -> 821145.6 | O7: 70/30 | P7: N
A8: Zoila Ortega Astor | B8: EH | C8: Agent | D8: Active | E8: 2026 | F8: 60000 | G8: 0.2 | H8: 1000000 | I8: =F8 -> 60000 | J8: =MIN(I8*(1+G8),H8) -> 72000 | K8: =MIN(J8*(1+G8),H8) -> 86400 | L8: =MIN(K8*(1+G8),H8) -> 103680 | M8: =MIN(L8*(1+G8),H8) -> 124416 | N8: =MIN(M8*(1+G8),H8) -> 149299.2 | O8: 70/30 | P8: N
A9: Scott Smith | B9: EH | C9: Agent | D9: Pending | E9: 2026 | F9: 50000 | G9: 0.2 | H9: 1000000 | I9: =F9 -> 50000 | J9: =MIN(I9*(1+G9),H9) -> 60000 | K9: =MIN(J9*(1+G9),H9) -> 72000 | L9: =MIN(K9*(1+G9),H9) -> 86400 | M9: =MIN(L9*(1+G9),H9) -> 103680 | N9: =MIN(M9*(1+G9),H9) -> 124416 | O9: 70/30 | P9: N
A10: Bonita DeWolf | B10: EH | C10: Agent | D10: Active | E10: 2024 | F10: 350000 | G10: 0.2 | H10: 1000000 | I10: =F10 -> 350000 | J10: =MIN(I10*(1+G10),H10) -> 420000 | K10: =MIN(J10*(1+G10),H10) -> 504000 | L10: =MIN(K10*(1+G10),H10) -> 604800 | M10: =MIN(L10*(1+G10),H10) -> 725760 | N10: =MIN(M10*(1+G10),H10) -> 870912 | O10: 70/30 | P10: N
A11: Sebastian Mobo | B11: EH | C11: Agent | D11: Active | E11: 2025 | F11: 100000 | G11: 0.2 | H11: 1000000 | I11: =F11 -> 100000 | J11: =MIN(I11*(1+G11),H11) -> 120000 | K11: =MIN(J11*(1+G11),H11) -> 144000 | L11: =MIN(K11*(1+G11),H11) -> 172800 | M11: =MIN(L11*(1+G11),H11) -> 207360 | N11: =MIN(M11*(1+G11),H11) -> 248832 | O11: 70/30 | P11: N
A12: Sandy Busch | B12: EH | C12: Agent | D12: Active | E12: 2025 | F12: 50000 | G12: 0.2 | H12: 1000000 | I12: =F12 -> 50000 | J12: =MIN(I12*(1+G12),H12) -> 60000 | K12: =MIN(J12*(1+G12),H12) -> 72000 | L12: =MIN(K12*(1+G12),H12) -> 86400 | M12: =MIN(L12*(1+G12),H12) -> 103680 | N12: =MIN(M12*(1+G12),H12) -> 124416 | O12: 70/30 | P12: N
A13: Jan Jaeger | B13: EH | C13: Agent | D13: Active | E13: 2024 | F13: 50000 | G13: 0.2 | H13: 1000000 | I13: =F13 -> 50000 | J13: =MIN(I13*(1+G13),H13) -> 60000 | K13: =MIN(J13*(1+G13),H13) -> 72000 | L13: =MIN(K13*(1+G13),H13) -> 86400 | M13: =MIN(L13*(1+G13),H13) -> 103680 | N13: =MIN(M13*(1+G13),H13) -> 124416 | O13: 70/30 | P13: N
A14: EXISTING SUBTOTAL | F14: =SUM(F5:F13) -> 1800000 | I14: =SUM(I5:I13) -> 1800000 | J14: =SUM(J5:J13) -> 2160000 | K14: =SUM(K5:K13) -> 2512000 | L14: =SUM(L5:L13) -> 2814400 | M14: =SUM(M5:M13) -> 3177280 | N14: =SUM(N5:N13) -> 3612736
A16: ENGINE 1: TARGETED HIRES — $500K-$1M (3/yr)
A17: TBD — Targeted 2026 #1 | B17: EH | C17: Sr Agent | D17: Recruiting | E17: 2026 | F17: 750000 | G17: 0.2 | H17: 1000000 | I17: =F17*0.5 -> 375000 | J17: =MIN(F17*(1+G17),H17) -> 900000 | K17: =MIN(J17*(1+G17),H17) -> 1000000 | L17: =MIN(K17*(1+G17),H17) -> 1000000 | M17: =MIN(L17*(1+G17),H17) -> 1000000 | N17: =MIN(M17*(1+G17),H17) -> 1000000 | O17: 70/30 | P17: N | Q17: $500K-$1M. 50% hire yr.
A18: TBD — Targeted 2026 #2 | B18: EH | C18: Sr Agent | D18: Recruiting | E18: 2026 | F18: 750000 | G18: 0.2 | H18: 1000000 | I18: =F18*0.5 -> 375000 | J18: =MIN(F18*(1+G18),H18) -> 900000 | K18: =MIN(J18*(1+G18),H18) -> 1000000 | L18: =MIN(K18*(1+G18),H18) -> 1000000 | M18: =MIN(L18*(1+G18),H18) -> 1000000 | N18: =MIN(M18*(1+G18),H18) -> 1000000 | O18: 70/30 | P18: N
A19: TBD — Targeted 2026 #3 | B19: EH | C19: Sr Agent | D19: Recruiting | E19: 2026 | F19: 750000 | G19: 0.2 | H19: 1000000 | I19: =F19*0.5 -> 375000 | J19: =MIN(F19*(1+G19),H19) -> 900000 | K19: =MIN(J19*(1+G19),H19) -> 1000000 | L19: =MIN(K19*(1+G19),H19) -> 1000000 | M19: =MIN(L19*(1+G19),H19) -> 1000000 | N19: =MIN(M19*(1+G19),H19) -> 1000000 | O19: 70/30 | P19: N
A20: TBD — Targeted 2027 #1 | B20: EH | C20: Sr Agent | D20: Planned | E20: 2027 | F20: 750000 | G20: 0.2 | H20: 1000000 | I20: 0 | J20: =F20*0.5 -> 375000 | K20: =MIN(F20*(1+G20),H20) -> 900000 | L20: =MIN(K20*(1+G20),H20) -> 1000000 | M20: =MIN(L20*(1+G20),H20) -> 1000000 | N20: =MIN(M20*(1+G20),H20) -> 1000000 | O20: 70/30 | P20: N
A21: TBD — Targeted 2027 #2 | B21: EH | C21: Sr Agent | D21: Planned | E21: 2027 | F21: 750000 | G21: 0.2 | H21: 1000000 | I21: 0 | J21: =F21*0.5 -> 375000 | K21: =MIN(F21*(1+G21),H21) -> 900000 | L21: =MIN(K21*(1+G21),H21) -> 1000000 | M21: =MIN(L21*(1+G21),H21) -> 1000000 | N21: =MIN(M21*(1+G21),H21) -> 1000000 | O21: 70/30 | P21: N
A22: TBD — Targeted 2027 #3 | B22: EH | C22: Sr Agent | D22: Planned | E22: 2027 | F22: 750000 | G22: 0.2 | H22: 1000000 | I22: 0 | J22: =F22*0.5 -> 375000 | K22: =MIN(F22*(1+G22),H22) -> 900000 | L22: =MIN(K22*(1+G22),H22) -> 1000000 | M22: =MIN(L22*(1+G22),H22) -> 1000000 | N22: =MIN(M22*(1+G22),H22) -> 1000000 | O22: 70/30 | P22: N
A23: TBD — Targeted 2028 #1 | B23: SH | C23: Sr Agent | D23: Planned | E23: 2028 | F23: 750000 | G23: 0.2 | H23: 1000000 | I23: 0 | J23: 0 | K23: =F23*0.5 -> 375000 | L23: =MIN(F23*(1+G23),H23) -> 900000 | M23: =MIN(L23*(1+G23),H23) -> 1000000 | N23: =MIN(M23*(1+G23),H23) -> 1000000 | O23: 70/30 | P23: N | Q23: Southampton
A24: TBD — Targeted 2028 #2 | B24: SH | C24: Sr Agent | D24: Planned | E24: 2028 | F24: 750000 | G24: 0.2 | H24: 1000000 | I24: 0 | J24: 0 | K24: =F24*0.5 -> 375000 | L24: =MIN(F24*(1+G24),H24) -> 900000 | M24: =MIN(L24*(1+G24),H24) -> 1000000 | N24: =MIN(M24*(1+G24),H24) -> 1000000 | O24: 70/30 | P24: N | Q24: Southampton
A25: TBD — Targeted 2028 #3 | B25: EH | C25: Sr Agent | D25: Planned | E25: 2028 | F25: 750000 | G25: 0.2 | H25: 1000000 | I25: 0 | J25: 0 | K25: =F25*0.5 -> 375000 | L25: =MIN(F25*(1+G25),H25) -> 900000 | M25: =MIN(L25*(1+G25),H25) -> 1000000 | N25: =MIN(M25*(1+G25),H25) -> 1000000 | O25: 70/30 | P25: N
A26: TARGETED SUBTOTAL | F26: =SUM(F17:F25) -> 6750000 | I26: =SUM(I17:I25) -> 1125000 | J26: =SUM(J17:J25) -> 3825000 | K26: =SUM(K17:K25) -> 6825000 | L26: =SUM(L17:L25) -> 8700000 | M26: =SUM(M17:M25) -> 9000000 | N26: =SUM(N17:N25) -> 9000000
A28: ENGINE 2: ORGANIC ADDS — $100K (4/yr)
A29: TBD — Organic 2026 #1 | B29: EH | C29: Agent | D29: Recruiting | E29: 2026 | F29: 100000 | G29: 0.2 | H29: 1000000 | I29: =F29*0.5 -> 50000 | J29: =MIN(F29*(1+G29),H29) -> 120000 | K29: =MIN(J29*(1+G29),H29) -> 144000 | L29: =MIN(K29*(1+G29),H29) -> 172800 | M29: =MIN(L29*(1+G29),H29) -> 207360 | N29: =MIN(M29*(1+G29),H29) -> 248832 | O29: 70/30 | P29: N
A30: TBD — Organic 2026 #2 | B30: EH | C30: Agent | D30: Recruiting | E30: 2026 | F30: 100000 | G30: 0.2 | H30: 1000000 | I30: =F30*0.5 -> 50000 | J30: =MIN(F30*(1+G30),H30) -> 120000 | K30: =MIN(J30*(1+G30),H30) -> 144000 | L30: =MIN(K30*(1+G30),H30) -> 172800 | M30: =MIN(L30*(1+G30),H30) -> 207360 | N30: =MIN(M30*(1+G30),H30) -> 248832 | O30: 70/30 | P30: N
A31: TBD — Organic 2026 #3 | B31: EH | C31: Agent | D31: Recruiting | E31: 2026 | F31: 100000 | G31: 0.2 | H31: 1000000 | I31: =F31*0.5 -> 50000 | J31: =MIN(F31*(1+G31),H31) -> 120000 | K31: =MIN(J31*(1+G31),H31) -> 144000 | L31: =MIN(K31*(1+G31),H31) -> 172800 | M31: =MIN(L31*(1+G31),H31) -> 207360 | N31: =MIN(M31*(1+G31),H31) -> 248832 | O31: 70/30 | P31: N
A32: TBD — Organic 2026 #4 | B32: EH | C32: Agent | D32: Recruiting | E32: 2026 | F32: 100000 | G32: 0.2 | H32: 1000000 | I32: =F32*0.5 -> 50000 | J32: =MIN(F32*(1+G32),H32) -> 120000 | K32: =MIN(J32*(1+G32),H32) -> 144000 | L32: =MIN(K32*(1+G32),H32) -> 172800 | M32: =MIN(L32*(1+G32),H32) -> 207360 | N32: =MIN(M32*(1+G32),H32) -> 248832 | O32: 70/30 | P32: N
A33: TBD — Organic 2027 #1 | B33: EH | C33: Agent | D33: Planned | E33: 2027 | F33: 100000 | G33: 0.2 | H33: 1000000 | I33: 0 | J33: =F33*0.5 -> 50000 | K33: =MIN(F33*(1+G33),H33) -> 120000 | L33: =MIN(K33*(1+G33),H33) -> 144000 | M33: =MIN(L33*(1+G33),H33) -> 172800 | N33: =MIN(M33*(1+G33),H33) -> 207360 | O33: 70/30 | P33: N
A34: TBD — Organic 2027 #2 | B34: EH | C34: Agent | D34: Planned | E34: 2027 | F34: 100000 | G34: 0.2 | H34: 1000000 | I34: 0 | J34: =F34*0.5 -> 50000 | K34: =MIN(F34*(1+G34),H34) -> 120000 | L34: =MIN(K34*(1+G34),H34) -> 144000 | M34: =MIN(L34*(1+G34),H34) -> 172800 | N34: =MIN(M34*(1+G34),H34) -> 207360 | O34: 70/30 | P34: N
A35: TBD — Organic 2027 #3 | B35: EH | C35: Agent | D35: Planned | E35: 2027 | F35: 100000 | G35: 0.2 | H35: 1000000 | I35: 0 | J35: =F35*0.5 -> 50000 | K35: =MIN(F35*(1+G35),H35) -> 120000 | L35: =MIN(K35*(1+G35),H35) -> 144000 | M35: =MIN(L35*(1+G35),H35) -> 172800 | N35: =MIN(M35*(1+G35),H35) -> 207360 | O35: 70/30 | P35: N
A36: TBD — Organic 2027 #4 | B36: EH | C36: Agent | D36: Planned | E36: 2027 | F36: 100000 | G36: 0.2 | H36: 1000000 | I36: 0 | J36: =F36*0.5 -> 50000 | K36: =MIN(F36*(1+G36),H36) -> 120000 | L36: =MIN(K36*(1+G36),H36) -> 144000 | M36: =MIN(L36*(1+G36),H36) -> 172800 | N36: =MIN(M36*(1+G36),H36) -> 207360 | O36: 70/30 | P36: N
A37: TBD — Organic 2028 #1 | B37: SH | C37: Agent | D37: Planned | E37: 2028 | F37: 100000 | G37: 0.2 | H37: 1000000 | I37: 0 | J37: 0 | K37: =F37*0.5 -> 50000 | L37: =MIN(F37*(1+G37),H37) -> 120000 | M37: =MIN(L37*(1+G37),H37) -> 144000 | N37: =MIN(M37*(1+G37),H37) -> 172800 | O37: 70/30 | P37: N
A38: TBD — Organic 2028 #2 | B38: SH | C38: Agent | D38: Planned | E38: 2028 | F38: 100000 | G38: 0.2 | H38: 1000000 | I38: 0 | J38: 0 | K38: =F38*0.5 -> 50000 | L38: =MIN(F38*(1+G38),H38) -> 120000 | M38: =MIN(L38*(1+G38),H38) -> 144000 | N38: =MIN(M38*(1+G38),H38) -> 172800 | O38: 70/30 | P38: N
A39: TBD — Organic 2028 #3 | B39: EH | C39: Agent | D39: Planned | E39: 2028 | F39: 100000 | G39: 0.2 | H39: 1000000 | I39: 0 | J39: 0 | K39: =F39*0.5 -> 50000 | L39: =MIN(F39*(1+G39),H39) -> 120000 | M39: =MIN(L39*(1+G39),H39) -> 144000 | N39: =MIN(M39*(1+G39),H39) -> 172800 | O39: 70/30 | P39: N
A40: TBD — Organic 2028 #4 | B40: EH | C40: Agent | D40: Planned | E40: 2028 | F40: 100000 | G40: 0.2 | H40: 1000000 | I40: 0 | J40: 0 | K40: =F40*0.5 -> 50000 | L40: =MIN(F40*(1+G40),H40) -> 120000 | M40: =MIN(L40*(1+G40),H40) -> 144000 | N40: =MIN(M40*(1+G40),H40) -> 172800 | O40: 70/30 | P40: N
A41: ORGANIC SUBTOTAL | F41: =SUM(F29:F40) -> 1200000 | I41: =SUM(I29:I40) -> 200000 | J41: =SUM(J29:J40) -> 680000 | K41: =SUM(K29:K40) -> 1256000 | L41: =SUM(L29:L40) -> 1747200 | M41: =SUM(M29:M40) -> 2096640 | N41: =SUM(N29:N40) -> 2515968
A43: GRAND TOTAL (ALL AGENTS) | F43: =F14+F26+F41 -> 9750000 | I43: =I14+I26+I41 -> 3125000 | J43: =J14+J26+J41 -> 6665000 | K43: =K14+K26+K41 -> 10593000 | L43: =L14+L26+L41 -> 13261600 | M43: =M14+M26+M41 -> 14273920 | N43: =N14+N26+N41 -> 15128704
A44: HOUSE TAKE (30%) | I44: =I43*0.3 -> 937500 | J44: =J43*0.3 -> 1999500 | K44: =K43*0.3 -> 3177900 | L44: =L43*0.3 -> 3978480 | M44: =M43*0.3 -> 4282176 | N44: =N43*0.3 -> 4538611.2
...

Sheet CONTACTS_STAGING
A1: NAME | B1: ROLE | C1: QUADRANT | D1: COMPANY | E1: PHONE | F1: EMAIL | G1: BIRTHDAY | H1: GIFT TRIGGER | I1: LAST GIFT | J1: CADENCE | K1: LAST TOUCH | L1: NEXT TOUCH DUE | M1: WHALE NOTES | N1: NOTES

Sheet ASSUMPTIONS
A2: GROWTH MODEL ASSUMPTIONS — BASE CASE
A3: PARAMETER | B3: VALUE | C3: NOTES
A4: Growth Rate | B4: 0.2 | C4: All agents until cap
A5: Cap | B5: 1000000 | C5: $1M max
A6: House Take | B6: 0.3 | C6: 30%
A7: Default Split | B7: 70/30 | C7: Agent/House
A8: Ed Split | B8: 50/50 | C8: MD rate
A9: Attrition | B9: 0.1 | C9: 10% base
A11: ENGINE 1: TARGETED
A12: Hires/Year | B12: 3 | C12: $500K-$1M producers
A13: Avg Y1 GCI | B13: 750000 | C13: Avg of range
A14: Hire Yr Weight | B14: 0.5 | C14: 50% mid-year
A16: ENGINE 2: ORGANIC
A17: Adds/Year | B17: 4 | C17: Brand-attracted
A18: Y1 GCI | B18: 100000 | C18: $100K base
A19: Hire Yr Weight | B19: 0.5 | C19: 50%
A21: EXPANSION
A22: East Hampton | B22: 2024 | C22: Flagship
A23: Southampton | B23: 2028 | C23: Target
A24: Westhampton | B24: 2030 | C24: Target
A26: INSTITUTIONAL / REFERRAL PIPELINE
A27: 2026_INSTITUTIONAL_PIPELINE_GCI | B27: 825000 | C27: Ilija network $450K + Auction house $125K + International council $100K + Retirement magnet early introductions $150K. Conservative Year 1 activation. Full detail in REFERRAL_PIPELINES tab — Sprint 6.

Sheet LEADERBOARD
A2: AGENT LEADERBOARD
A4: TOP PRODUCERS (2026)
A5: RANK | B5: AGENT | C5: OFFICE | D5: 2026 GCI | E5: TYPE | F5: STATUS | G5: PIPELINE VALUE | H5: CLOSE RATE | I5: LEVERAGE NEED
A6: 1 | B6: Ed Bruehl | C6: EH | D6: =ROSTER!I5 -> 750000 | E6: Existing | F6: At Cap
A7: 2 | B7: Jarvis Slade | C7: EH | D7: =ROSTER!I7 -> 330000 | E7: Existing | F7: Active
A8: 3 | B8: TBD Tgt 2026 #1 | C8: EH | D8: =ROSTER!I17 -> 375000 | E8: Targeted | F8: Recruiting
A9: 4 | B9: TBD Tgt 2026 #2 | C9: EH | D9: =ROSTER!I18 -> 375000 | E9: Targeted | F9: Recruiting
A10: 5 | B10: TBD Tgt 2026 #3 | C10: EH | D10: =ROSTER!I19 -> 375000 | E10: Targeted | F10: Recruiting
A11: 6 | B11: Bonita DeWolf | C11: EH | D11: =ROSTER!I10 -> 350000 | E11: Existing | F11: Active
A12: 7 | B12: Angel Theodore | C12: EH | D12: =ROSTER!I6 -> 60000 | E12: Existing | F12: Active
A13: 8 | B13: Zoila Ortega Astor | C13: EH | D13: =ROSTER!I8 -> 60000 | E13: Existing | F13: Active
A14: 9 | B14: Sebastian Mobo | C14: EH | D14: =ROSTER!I11 -> 100000 | E14: Existing | F14: Active
A15: 10 | B15: Sandy Busch | C15: EH | D15: =ROSTER!I12 -> 50000 | E15: Existing | F15: Active
A16: 11 | B16: Jan Jaeger | C16: EH | D16: =ROSTER!I13 -> 50000 | E16: Existing | F16: Active
A18: RECRUITING PIPELINE
A19: SLOT | B19: OFFICE | C19: START | D19: Y1 GCI | E19: STATUS | F19: CANDIDATE | G19: SOURCE | H19: NEXT STEP | I19: NOTES
A20: =ROSTER!A17 -> TBD — Targeted 2026 #1 | B20: =ROSTER!B17 -> EH | C20: =ROSTER!E17 -> 2026 | D20: =ROSTER!F17 -> 750000 | E20: =ROSTER!D17 -> Recruiting
A21: =ROSTER!A18 -> TBD — Targeted 2026 #2 | B21: =ROSTER!B18 -> EH | C21: =ROSTER!E18 -> 2026 | D21: =ROSTER!F18 -> 750000 | E21: =ROSTER!D18 -> Recruiting
A22: =ROSTER!A19 -> TBD — Targeted 2026 #3 | B22: =ROSTER!B19 -> EH | C22: =ROSTER!E19 -> 2026 | D22: =ROSTER!F19 -> 750000 | E22: =ROSTER!D19 -> Recruiting
A23: =ROSTER!A20 -> TBD — Targeted 2027 #1 | B23: =ROSTER!B20 -> EH | C23: =ROSTER!E20 -> 2027 | D23: =ROSTER!F20 -> 750000 | E23: =ROSTER!D20 -> Planned
A24: =ROSTER!A21 -> TBD — Targeted 2027 #2 | B24: =ROSTER!B21 -> EH | C24: =ROSTER!E21 -> 2027 | D24: =ROSTER!F21 -> 750000 | E24: =ROSTER!D21 -> Planned
A25: =ROSTER!A22 -> TBD — Targeted 2027 #3 | B25: =ROSTER!B22 -> EH | C25: =ROSTER!E22 -> 2027 | D25: =ROSTER!F22 -> 750000 | E25: =ROSTER!D22 -> Planned
A26: =ROSTER!A23 -> TBD — Targeted 2028 #1 | B26: =ROSTER!B23 -> SH | C26: =ROSTER!E23 -> 2028 | D26: =ROSTER!F23 -> 750000 | E26: =ROSTER!D23 -> Planned
A27: =ROSTER!A24 -> TBD — Targeted 2028 #2 | B27: =ROSTER!B24 -> SH | C27: =ROSTER!E24 -> 2028 | D27: =ROSTER!F24 -> 750000 | E27: =ROSTER!D24 -> Planned
A28: =ROSTER!A25 -> TBD — Targeted 2028 #3 | B28: =ROSTER!B25 -> EH | C28: =ROSTER!E25 -> 2028 | D28: =ROSTER!F25 -> 750000 | E28: =ROSTER!D25 -> Planned
A30: AT RISK (120+ DAYS NO CLOSE)
A31: AGENT | B31: OFFICE | C31: LAST DEAL | D31: DAYS | E31: GCI vs TARGET | F31: RISK | G31: ACTION

Sheet OUTPUTS
A2: DASHBOARD FEED — BASE CASE
A4: KPI STRIP
A5: 2026 GCI | B5: =ROSTER!I43 -> 3125000 | C5: AGENTS | D5: =ROSTER!I45 -> 18 | E5: HOUSE TAKE | F5: =ROSTER!I44 -> 937500 | G5: SOUTHAMPTON | H5: 2028 | I5: WESTHAMPTON | J5: 2030
A7: NEXT 12 MONTHS
A8: OFFICE | B8: AGENTS | C8: GCI | D8: HOUSE TAKE | E8: NOTES
A9: East Hampton | B9: =ROSTER!I45 -> 18 | C9: =ROSTER!I43 -> 3125000 | D9: =C9*0.3 -> 937500 | E9: 8 existing + 3 targeted + 4 organic
A10: Southampton | E10: Launch 2028
A11: Westhampton | E11: Launch 2030
A12: TOTAL | B12: =B9 -> 18 | C12: =C9 -> 3125000 | D12: =D9 -> 937500
A14: 2026-2031 OUTLOOK
A15: YEAR | B15: AGENTS | C15: EXISTING | D15: TARGETED | E15: ORGANIC | F15: TOTAL GCI | G15: HOUSE TAKE | H15: AVG/AGENT
A16: 2026 | B16: =ROSTER!I45 -> 18 | C16: =ROSTER!I14 -> 1800000 | D16: =ROSTER!I26 -> 1125000 | E16: =ROSTER!I41 -> 200000 | F16: =ROSTER!I43 -> 3125000 | G16: =F16*0.3 -> 937500 | H16: =IF(B16>0,F16/B16,0) -> 173611.11
A17: 2027 | B17: =ROSTER!J45 -> 25 | C17: =ROSTER!J14 -> 2160000 | D17: =ROSTER!J26 -> 3825000 | E17: =ROSTER!J41 -> 680000 | F17: =ROSTER!J43 -> 6665000 | G17: =F17*0.3 -> 1999500 | H17: =IF(B17>0,F17/B17,0) -> 266600
A18: 2028 | B18: =ROSTER!K45 -> 32 | C18: =ROSTER!K14 -> 2512000 | D18: =ROSTER!K26 -> 6825000 | E18: =ROSTER!K41 -> 1256000 | F18: =ROSTER!K43 -> 10593000 | G18: =F18*0.3 -> 3177900 | H18: =IF(B18>0,F18/B18,0) -> 331031.25
A19: 2029 | B19: =ROSTER!L45 -> 32 | C19: =ROSTER!L14 -> 2814400 | D19: =ROSTER!L26 -> 8700000 | E19: =ROSTER!L41 -> 1747200 | F19: =ROSTER!L43 -> 13261600 | G19: =F19*0.3 -> 3978480 | H19: =IF(B19>0,F19/B19,0) -> 414425
A20: 2030 | B20: =ROSTER!M45 -> 32 | C20: =ROSTER!M14 -> 3177280 | D20: =ROSTER!M26 -> 9000000 | E20: =ROSTER!M41 -> 2096640 | F20: =ROSTER!M43 -> 14273920 | G20: =F20*0.3 -> 4282176 | H20: =IF(B20>0,F20/B20,0) -> 446060
A21: 2031 | B21: =ROSTER!N45 -> 32 | C21: =ROSTER!N14 -> 3612736 | D21: =ROSTER!N26 -> 9000000 | E21: =ROSTER!N41 -> 2515968 | F21: =ROSTER!N43 -> 15128704 | G21: =F21*0.3 -> 4538611.2 | H21: =IF(B21>0,F21/B21,0) -> 472772
A23: 2026 GCI BREAKDOWN
A24: Agent Production GCI 2026 | B24: =ROSTER!I43 -> 3125000
A25: Institutional / Referral GCI 2026 | B25: =ASSUMPTIONS!B27 -> 825000
A26: Total GCI 2026 | B26: =B24+B25 -> 3950000
A27: House Take 2026 (30%) | B27: =B26*0.3 -> 1185000
